<?xml version="1.0"?>
<robot name="kuka_lwr" xmlns:xacro="http://www.ros.org/wiki/xacro">

	<!-- utils /-->
	<xacro:include filename="$(find lwr_description)/model/utils.xacro"/>
	<xacro:include filename="$(find lwr_description)/model/kuka_materials.xacro"/>

	<!-- gazebo and transmission models /-->
	<xacro:include filename="$(find lwr_description)/model/kuka_lwr.gazebo.xacro"/>
	<xacro:include filename="$(find lwr_description)/model/kuka_lwr.transmission.xacro"/>
	<xacro:include filename="$(find lwr_description)/model/kuka_lwr.stiffness_damping_addtorque.xacro"/>

	<!-- properties /-->
	<xacro:property name="base_mass" value="2.0"/>
	<xacro:property name="link_mass" value="2.35"/>
    <xacro:property name="wrist_mass" value="1.1"/>
    <xacro:property name="tip_mass" value="0.25"/>
	<xacro:property name="velocity_scale" value="1"/>
	<xacro:property name="effort_scale" value="1"/>
	<xacro:property name="use_extra_joints_default" value="true"/>
	<xacro:property name="inertia_scale" value="10000000.0"/>

	<!-- URDF model /-->
	<xacro:macro name="kuka_lwr" params="parent name *origin use_extra_joints:=${use_extra_joints_default}">

		<!-- First (shoulder) element of the arm. Fixed to its parent. -->
		<joint name="${parent}_${name}_base_joint" type="fixed">
			<xacro:insert_block name="origin"/>
			<origin xyz="0 0 0" rpy="0 0 0"/>
			<parent link="${parent}"/>
			<child link="${name}_base_link"/>
		</joint>

		<link name="${name}_base_link">
			<inertial>
				<mass value="${base_mass}"/>
				<origin xyz="0 0 0.055"  />
				<cylinder_inertia_def radius="0.06" length="0.11" mass="${base_mass}"/>
			</inertial>
			<visual>
				<origin xyz="0 0 0" rpy="0 0 ${M_PI}"/>
				<geometry>
					<mesh filename="package://lwr_description/meshes/lwr4plus/visual/base.STL"/>
				</geometry>
				<material name="Kuka/Orange"/>
			</visual>
			<collision>
				<origin xyz="0 0 0.055" rpy="0 0 ${M_PI}"/>
				<geometry>
					<cylinder radius="0.07" length="0.11"/>
				</geometry>
			</collision>
		</link>

		<!-- Second segment of the arm. Joint along z-axis -->
		<joint name="${name}_a1_joint" type="revolute">
			<origin xyz="0 0 0.11" rpy="0 0 0"/>
			<axis xyz="0 0 1"/>
			<limit lower="${-170 * M_PI / 180}" upper="${170 * M_PI / 180}" effort="176" velocity="${velocity_scale * 110 * M_PI / 180}" />
			<dynamics friction="1.0" damping="0.7"/>
			<parent link="${name}_base_link"/>
			<child link="${name}_1_link"/>
		</joint>

		<link name="${name}_1_link">
			<inertial>
				<mass value="${link_mass}"/>
				<origin rpy="0 0 0" xyz="0.00000301 0.02391176 0.11939403"/>
			    <inertia ixx="${136938.093750 / inertia_scale}" ixy="${4.968005 / inertia_scale}" ixz="${8.730822 / inertia_scale}" iyy="${135390.187500 / inertia_scale}" iyz="${-23715.781250 / inertia_scale}" izz="${40896.656250 / inertia_scale}" />
			</inertial>
			<visual>
				<origin xyz="0 0 -0.008" rpy="0 0 ${M_PI}"/>
				<geometry>
					<mesh filename="package://lwr_description/meshes/lwr4plus/visual/link_1.STL"/>
				</geometry>
				<material name="Kuka/Orange"/>
			</visual>
			<collision>
				<origin xyz="0 0 0.0" rpy="0 0 0"/>
				<geometry>
					<sphere radius="0.07"/>
				</geometry>
			</collision>
			<collision>
				<origin xyz="0 0.06 0.2" rpy="0 0 0"/>
				<geometry>
					<sphere radius="0.07"/>
				</geometry>
			</collision>
			<collision>
				<origin xyz="0 0.03 0.1" rpy="-0.291 0 0"/>
				<geometry>
					<cylinder radius="0.07" length="0.208"/>
				</geometry>
			</collision>
		</link>

		<!-- Third segment of the arm. Joint along y-axis -->
		<joint name="${name}_a2_joint" type="revolute">
			<origin xyz="0 0 0.2005" rpy="0 0 0"/>
			<axis xyz="0 -1 0"/>
			<limit lower="${-120 * M_PI / 180}" upper="${120 * M_PI / 180}" effort="176" velocity="${velocity_scale * 110 * M_PI / 180}" />
			<dynamics friction="1.0" damping="0.7"/>
			<parent link="${name}_1_link"/>
			<child link="${name}_2_link"/>
		</joint>

		<link name="${name}_2_link">
			<inertial>
				<mass value="${link_mass}"/>
				<origin rpy="0 0 0" xyz="0.00000301 -0.02391175 0.08110597"/>
			    <inertia ixx="${136938.093750 / inertia_scale}" ixy="${-4.968005 / inertia_scale}" ixz="${-8.730822 / inertia_scale}" iyy="${135390.187500 / inertia_scale}" iyz="${-23715.781250 / inertia_scale}" izz="${40896.656250 / inertia_scale}" />
			</inertial>
			<visual>
				<origin xyz="0 0 0.0" rpy="0 0 ${M_PI}"/>
				<geometry>
					<mesh filename="package://lwr_description/meshes/lwr4plus/visual/link_2.STL"/>
				</geometry>
				<material name="Kuka/Orange"/>
			</visual>
			<collision>
				<origin xyz="0 0 0.2" rpy="0 0 0"/>
				<geometry>
					<sphere radius="0.07"/>
				</geometry>
			</collision>
			<collision>
				<origin xyz="0 -0.06 0.0" rpy="0 0 0"/>
				<geometry>
					<sphere radius="0.07"/>
				</geometry>
			</collision>
			<collision>
				<origin xyz="0 -0.03 0.1" rpy="-0.291 0 0"/>
				<geometry>
					<cylinder radius="0.07" length="0.208"/>
				</geometry>
			</collision>
		</link>

		<!-- Fourth element of the arm. z-axis -->
		<joint name="${name}_e1_joint" type="revolute">
			<origin xyz="0 0 0.20" rpy="0 0 0"/>
			<axis xyz="0 0 1"/>
			<limit lower="${-170 * M_PI / 180}" upper="${170 * M_PI / 180}" effort="100" velocity="${velocity_scale * 128 * M_PI / 180}" />
			<dynamics friction="1.0" damping="0.7"/>
			<parent link="${name}_2_link"/>
			<child link="${name}_3_link"/>
		</joint>

		<link name="${name}_3_link">
			<inertial>
				<mass value="${link_mass}"/>
				<origin rpy="0 0 0" xyz="-0.00000302 -.02391175 0.11939403"/>
			    <inertia ixx="${136938.093750 / inertia_scale}" ixy="${4.968005 / inertia_scale}" ixz="${-8.730822 / inertia_scale}" iyy="${135390.187500 / inertia_scale}" iyz="${23715.781250 / inertia_scale}" izz="${40896.656250 / inertia_scale}" />
			</inertial>
			<visual>
				<origin xyz="0 0 -0.008" rpy="0 0 ${M_PI}"/>
				<geometry>
					<mesh filename="package://lwr_description/meshes/lwr4plus/visual/link_3.STL"/>
				</geometry>
				<material name="Kuka/Orange"/>
			</visual>
			<collision>
				<origin xyz="0 0 0.0" rpy="0 0 0"/>
				<geometry>
					<sphere radius="0.07"/>
				</geometry>
			</collision>
			<collision>
				<origin xyz="0 -0.06 0.2" rpy="0 0 0"/>
				<geometry>
					<sphere radius="0.07"/>
				</geometry>
			</collision>
			<collision>
				<origin xyz="0 -0.03 0.1" rpy="0.291 0 0"/>
				<geometry>
					<cylinder radius="0.07" length="0.208"/>
				</geometry>
			</collision>
		</link>

		<!-- fifth element of the arm. x-axis -->
		<joint name="${name}_a3_joint" type="revolute">
			<origin xyz="0 0 0.20" rpy="0 0 0"/>
			<axis xyz="0 1 0"/>
			<limit lower="${-120 * M_PI / 180}" upper="${120 * M_PI / 180}" effort="100" velocity="${velocity_scale * 128 * M_PI / 180}" />
			<dynamics friction="1.0" damping="0.7"/>
			<parent link="${name}_3_link"/>
			<child link="${name}_4_link"/>
		</joint>

		<link name="${name}_4_link">
			<inertial>
				<mass value="${link_mass}"/>
				<origin rpy="0 0 0" xyz="-0.00000303 .02391175 0.08110597"/>
			    <inertia ixx="${136938.093750 / inertia_scale}" ixy="${-4.968005 / inertia_scale}" ixz="${8.730822 / inertia_scale}" iyy="${135390.187500 / inertia_scale}" iyz="${23715.781250 / inertia_scale}" izz="${40896.656250 / inertia_scale}" />
			</inertial>
			<visual>
				<origin xyz="0 0 0.0" rpy="0 0 ${M_PI}"/>
				<geometry>
					<mesh filename="package://lwr_description/meshes/lwr4plus/visual/link_4.STL"/>
				</geometry>
				<material name="Kuka/Orange"/>
			</visual>
			<collision>
			<origin xyz="0 0 0.2" rpy="0 0 0"/>
			<geometry>
				<sphere radius="0.07"/>
			</geometry>
			</collision>
			<collision>
				<origin xyz="0 0.06 0.0" rpy="0 0 0"/>
				<geometry>
					<sphere radius="0.07"/>
				</geometry>
			</collision>
			<collision>
				<origin xyz="0 0.03 0.1" rpy="0.291 0 0"/>
				<geometry>
					<cylinder radius="0.07" length="0.208"/>
				</geometry>
			</collision>
		</link>

		<!-- Sixth element of the arm. z-axis -->
		<joint name="${name}_a4_joint" type="revolute">
			<origin xyz="0 0 0.20" rpy="0 0 0"/>
			<axis xyz="0 0 1"/>
			<limit lower="${-170 * M_PI / 180}" upper="${170 * M_PI / 180}" effort="100" velocity="${velocity_scale * 204 * M_PI / 180}" />
			<dynamics friction="1.0" damping="0.7"/>
			<parent link="${name}_4_link"/>
			<child link="${name}_5_link"/>
		</joint>

		<link name="${name}_5_link">
			<inertial>
				<mass value="${link_mass}"/>
				<origin rpy="0 0 0" xyz="-0.00000303 .02391175 0.08110597"/>
			    <inertia ixx="${82625.953125 / inertia_scale}" ixy="${5.603518 / inertia_scale}" ixz="${8.553005 / inertia_scale}" iyy="${76228.593750 / inertia_scale}" iyz="${-24984.386719 / inertia_scale}" izz="${33607.035156 / inertia_scale}" />
			</inertial>
			<visual>
				<origin xyz="0 0 -0.008" rpy="0 0 ${M_PI}"/>
				<geometry name="${name}_5_geom">
					<mesh filename="package://lwr_description/meshes/lwr4plus/visual/link_5.STL"/>
				</geometry>
				<material name="Kuka/Orange"/>
			</visual>

			<collision>
				<origin xyz="0 0 0.0" rpy="0 0 0"/>
				<geometry>
					<sphere radius="0.07"/>
				</geometry>
			</collision>
			<collision>
				<origin xyz="0 0.04 0.19" rpy="0 0 0"/>
				<geometry>
					<sphere radius="0.07"/>
				</geometry>
			</collision>
			<collision>
				<origin xyz="0 0.02 0.095" rpy="-0.207 0 0"/>
				<geometry>
					<cylinder radius="0.07" length="0.198"/>
				</geometry>
			</collision>
		</link>

		<!-- Seventh element of the arm. z-axis -->
		<joint name="${name}_a5_joint" type="revolute">
			<origin xyz="0 0 0.19" rpy="0 0 0"/>
			<axis xyz="0 -1 0"/>
			<limit lower="${-120 * M_PI / 180}" upper="${120 * M_PI / 180}" effort="38" velocity="${velocity_scale * 184 * M_PI / 180}" />
			<dynamics friction="1.0" damping="0.7"/>
			<parent link="${name}_5_link"/>
			<child link="${name}_6_link"/>
		</joint>

		<link name="${name}_6_link">
			<inertial>
				<mass value="${wrist_mass}"/>
				<origin rpy="0 0 0" xyz="-0.00000001 -.00447585 -0.00290105"/>
			    <inertia ixx="${29610.587891 / inertia_scale}" ixy="${-0.002319 / inertia_scale}" ixz="${0.023622 / inertia_scale}" iyy="${29691.074219 / inertia_scale}" iyz="${246.776962 / inertia_scale}" izz="${32060.654297 / inertia_scale}" />
			</inertial>

			<visual>
				<origin xyz="0 0 0" rpy="0 0 ${M_PI}"/>
				<geometry>
					<mesh filename="package://lwr_description/meshes/lwr4plus/visual/link_6.STL"/>
				</geometry>
			<material name="Kuka/Grey"/>
			</visual>
			<collision>
			<origin xyz="0 -0.01 0" rpy="0 0 ${M_PI}"/>
			<geometry>
				<sphere radius="0.08"/>
			</geometry>
			</collision>
		</link>

		<!-- Eighth element of the arm. z-axis -->
		<joint name="${name}_a6_joint" type="revolute">
			<origin xyz="0 0 0.078" rpy="0 0 0"/>
			<axis xyz="0 0 1"/>
			<limit lower="${-170 * M_PI / 180}" upper="${170 * M_PI / 180}" effort="38" velocity="${velocity_scale * 184 * M_PI / 180}" />
			<dynamics friction="1.0" damping="0.7"/>
			<parent link="${name}_6_link"/>
			<child link="${name}_7_link"/>
		</joint>

		<link name="${name}_7_link">
			<inertial>
				<mass value="${tip_mass}"/>
			    <origin xyz="0 0 -0.014685" rpy="0 0 0"/>
			    <!-- <inertia ixx="${414.478149 / inertia_scale}" ixy="0.0" ixz="0.0" iyy="${414.478149 / inertia_scale}" iyz="0.0" izz="${694.374329 / inertia_scale}" /> -->
        		<!-- <inertia ixx="${2 * tip_mass * 0.1 * 0.1 / 5}"  ixy="0"  ixz="0" iyy="${2 * tip_mass * 0.1 * 0.1 / 5}" iyz="0" izz="${2 * tip_mass * 0.1 * 0.1 / 5}" /> -->
        		<inertia ixx="${1 / 12  * (3 * 0.05 * 0.05 + 0.01 * 0.01)}"  ixy="0"  ixz="0" iyy="${1 / 12  * (3 * 0.05 * 0.05 + 0.01 * 0.01)}" iyz="0" izz="${1 / 12  * (3 * 0.05 * 0.05 + 0.01 * 0.01)}" />
			</inertial>
			<visual>
				<origin xyz="0 0 0" rpy="0 0 ${M_PI}"/>
				<geometry>
					<mesh filename="package://lwr_description/meshes/lwr4plus/visual/link_7.STL"/>
				</geometry>
			<material name="Kuka/DarkGrey"/>
			</visual>
<!-- 
			<collision>
			<origin xyz="0 0 -0.005" rpy="0 0 ${M_PI}"/>
			<geometry>
				<cylinder radius="0.04" length="0.01"/>
			</geometry>
			</collision> -->
		</link>

		<xacro:kuka_lwr_gazebo name="${name}"/>
		<xacro:kuka_lwr_transmission name="${name}"/>
		<xacro:if value = "${use_extra_joints}">
			<xacro:kuka_lwr_stiffness_damping_addtorque name="${name}"/>
		</xacro:if>


	</xacro:macro>

</robot>
